[2024-06-08T05:15:22.967+0000] {local_task_job_runner.py:120} INFO - ::group::Pre task execution logs
[2024-06-08T05:15:22.984+0000] {taskinstance.py:2076} INFO - Dependencies all met for dep_context=non-requeueable deps ti=<TaskInstance: zillow_analytics_dag.tsk_load_to_s3 manual__2024-06-08T05:15:17.652030+00:00 [queued]>
[2024-06-08T05:15:22.990+0000] {taskinstance.py:2076} INFO - Dependencies all met for dep_context=requeueable deps ti=<TaskInstance: zillow_analytics_dag.tsk_load_to_s3 manual__2024-06-08T05:15:17.652030+00:00 [queued]>
[2024-06-08T05:15:22.991+0000] {taskinstance.py:2306} INFO - Starting attempt 1 of 3
[2024-06-08T05:15:23.005+0000] {taskinstance.py:2330} INFO - Executing <Task(BashOperator): tsk_load_to_s3> on 2024-06-08 05:15:17.652030+00:00
[2024-06-08T05:15:23.010+0000] {standard_task_runner.py:63} INFO - Started process 61506 to run task
[2024-06-08T05:15:23.013+0000] {standard_task_runner.py:90} INFO - Running: ['airflow', 'tasks', 'run', 'zillow_analytics_dag', 'tsk_load_to_s3', 'manual__2024-06-08T05:15:17.652030+00:00', '--job-id', '45', '--raw', '--subdir', 'DAGS_FOLDER/zillowanalytics.py', '--cfg-path', '/tmp/tmpv9gwn_w9']
[2024-06-08T05:15:23.014+0000] {standard_task_runner.py:91} INFO - Job 45: Subtask tsk_load_to_s3
[2024-06-08T05:15:23.052+0000] {task_command.py:426} INFO - Running <TaskInstance: zillow_analytics_dag.tsk_load_to_s3 manual__2024-06-08T05:15:17.652030+00:00 [running]> on host ip-172-31-25-20.us-east-2.compute.internal
[2024-06-08T05:15:23.123+0000] {taskinstance.py:2648} INFO - Exporting env vars: AIRFLOW_CTX_DAG_EMAIL='myemail@domain.com' AIRFLOW_CTX_DAG_OWNER='airflow' AIRFLOW_CTX_DAG_ID='zillow_analytics_dag' AIRFLOW_CTX_TASK_ID='tsk_load_to_s3' AIRFLOW_CTX_EXECUTION_DATE='2024-06-08T05:15:17.652030+00:00' AIRFLOW_CTX_TRY_NUMBER='1' AIRFLOW_CTX_DAG_RUN_ID='manual__2024-06-08T05:15:17.652030+00:00'
[2024-06-08T05:15:23.123+0000] {taskinstance.py:430} INFO - ::endgroup::
[2024-06-08T05:15:23.136+0000] {subprocess.py:63} INFO - Tmp dir root location: /tmp
[2024-06-08T05:15:23.136+0000] {subprocess.py:75} INFO - Running command: ['/usr/bin/bash', '-c', 'aws s3 mv /home/ubuntu/response_data_(dt_string).json s3://endtoend-zillow/']
[2024-06-08T05:15:23.144+0000] {subprocess.py:86} INFO - Output:
[2024-06-08T05:15:23.145+0000] {subprocess.py:93} INFO - /usr/bin/bash: -c: line 1: syntax error near unexpected token `('
[2024-06-08T05:15:23.145+0000] {subprocess.py:93} INFO - /usr/bin/bash: -c: line 1: `aws s3 mv /home/ubuntu/response_data_(dt_string).json s3://endtoend-zillow/'
[2024-06-08T05:15:23.146+0000] {subprocess.py:97} INFO - Command exited with return code 2
[2024-06-08T05:15:23.146+0000] {taskinstance.py:441} INFO - ::group::Post task execution logs
[2024-06-08T05:15:23.155+0000] {taskinstance.py:2905} ERROR - Task failed with exception
Traceback (most recent call last):
  File "/home/ubuntu/endtoend_venv/lib/python3.12/site-packages/airflow/models/taskinstance.py", line 465, in _execute_task
    result = _execute_callable(context=context, **execute_callable_kwargs)
             ^^^^^^^^^^^^^^^^^^^^^^^^^^^^^^^^^^^^^^^^^^^^^^^^^^^^^^^^^^^^^
  File "/home/ubuntu/endtoend_venv/lib/python3.12/site-packages/airflow/models/taskinstance.py", line 432, in _execute_callable
    return execute_callable(context=context, **execute_callable_kwargs)
           ^^^^^^^^^^^^^^^^^^^^^^^^^^^^^^^^^^^^^^^^^^^^^^^^^^^^^^^^^^^^
  File "/home/ubuntu/endtoend_venv/lib/python3.12/site-packages/airflow/models/baseoperator.py", line 400, in wrapper
    return func(self, *args, **kwargs)
           ^^^^^^^^^^^^^^^^^^^^^^^^^^^
  File "/home/ubuntu/endtoend_venv/lib/python3.12/site-packages/airflow/operators/bash.py", line 243, in execute
    raise AirflowException(
airflow.exceptions.AirflowException: Bash command failed. The command returned a non-zero exit code 2.
[2024-06-08T05:15:23.158+0000] {taskinstance.py:1206} INFO - Marking task as UP_FOR_RETRY. dag_id=zillow_analytics_dag, task_id=tsk_load_to_s3, run_id=manual__2024-06-08T05:15:17.652030+00:00, execution_date=20240608T051517, start_date=20240608T051522, end_date=20240608T051523
[2024-06-08T05:15:23.170+0000] {standard_task_runner.py:110} ERROR - Failed to execute job 45 for task tsk_load_to_s3 (Bash command failed. The command returned a non-zero exit code 2.; 61506)
[2024-06-08T05:15:23.185+0000] {local_task_job_runner.py:240} INFO - Task exited with return code 1
[2024-06-08T05:15:23.196+0000] {taskinstance.py:3498} INFO - 0 downstream tasks scheduled from follow-on schedule check
[2024-06-08T05:15:23.197+0000] {local_task_job_runner.py:222} INFO - ::endgroup::
