[2024-06-14T02:19:53.556+0000] {local_task_job_runner.py:120} INFO - ::group::Pre task execution logs
[2024-06-14T02:19:53.565+0000] {taskinstance.py:2076} INFO - Dependencies all met for dep_context=non-requeueable deps ti=<TaskInstance: zillow_analytics_dag.tsk_is_file_in_s3_available manual__2024-06-14T02:19:44.203462+00:00 [queued]>
[2024-06-14T02:19:53.572+0000] {taskinstance.py:2076} INFO - Dependencies all met for dep_context=requeueable deps ti=<TaskInstance: zillow_analytics_dag.tsk_is_file_in_s3_available manual__2024-06-14T02:19:44.203462+00:00 [queued]>
[2024-06-14T02:19:53.572+0000] {taskinstance.py:2306} INFO - Starting attempt 1 of 3
[2024-06-14T02:19:53.586+0000] {taskinstance.py:2330} INFO - Executing <Task(S3KeySensor): tsk_is_file_in_s3_available> on 2024-06-14 02:19:44.203462+00:00
[2024-06-14T02:19:53.591+0000] {standard_task_runner.py:63} INFO - Started process 155179 to run task
[2024-06-14T02:19:53.594+0000] {standard_task_runner.py:90} INFO - Running: ['airflow', 'tasks', 'run', 'zillow_analytics_dag', 'tsk_is_file_in_s3_available', 'manual__2024-06-14T02:19:44.203462+00:00', '--job-id', '137', '--raw', '--subdir', 'DAGS_FOLDER/zillowanalytics.py', '--cfg-path', '/tmp/tmpbpuhfbsg']
[2024-06-14T02:19:53.596+0000] {standard_task_runner.py:91} INFO - Job 137: Subtask tsk_is_file_in_s3_available
[2024-06-14T02:19:53.630+0000] {task_command.py:426} INFO - Running <TaskInstance: zillow_analytics_dag.tsk_is_file_in_s3_available manual__2024-06-14T02:19:44.203462+00:00 [running]> on host ip-172-31-25-20.us-east-2.compute.internal
[2024-06-14T02:19:53.703+0000] {taskinstance.py:2648} INFO - Exporting env vars: AIRFLOW_CTX_DAG_EMAIL='myemail@domain.com' AIRFLOW_CTX_DAG_OWNER='airflow' AIRFLOW_CTX_DAG_ID='zillow_analytics_dag' AIRFLOW_CTX_TASK_ID='tsk_is_file_in_s3_available' AIRFLOW_CTX_EXECUTION_DATE='2024-06-14T02:19:44.203462+00:00' AIRFLOW_CTX_TRY_NUMBER='1' AIRFLOW_CTX_DAG_RUN_ID='manual__2024-06-14T02:19:44.203462+00:00'
[2024-06-14T02:19:53.704+0000] {taskinstance.py:430} INFO - ::endgroup::
[2024-06-14T02:19:53.716+0000] {baseoperator.py:399} WARNING - S3KeySensor.execute cannot be called outside TaskInstance!
[2024-06-14T02:19:53.717+0000] {s3.py:117} INFO - Poking for key : s3://cleaned-data-zone-csv-bucket-ng/response_data_14062024021947.csv
[2024-06-14T02:19:53.721+0000] {base.py:84} INFO - Using connection ID 'aws_s3_conn' for task execution.
[2024-06-14T02:19:53.722+0000] {connection_wrapper.py:384} INFO - AWS Connection (conn_id='aws_s3_conn', conn_type='aws') credentials retrieved from login and password.
[2024-06-14T02:19:59.117+0000] {s3.py:117} INFO - Poking for key : s3://cleaned-data-zone-csv-bucket-ng/response_data_14062024021947.csv
[2024-06-14T02:20:04.129+0000] {s3.py:117} INFO - Poking for key : s3://cleaned-data-zone-csv-bucket-ng/response_data_14062024021947.csv
[2024-06-14T02:20:09.138+0000] {s3.py:117} INFO - Poking for key : s3://cleaned-data-zone-csv-bucket-ng/response_data_14062024021947.csv
[2024-06-14T02:20:14.149+0000] {s3.py:117} INFO - Poking for key : s3://cleaned-data-zone-csv-bucket-ng/response_data_14062024021947.csv
[2024-06-14T02:20:14.157+0000] {taskinstance.py:441} INFO - ::group::Post task execution logs
[2024-06-14T02:20:14.157+0000] {taskinstance.py:2905} ERROR - Task failed with exception
Traceback (most recent call last):
  File "/home/ubuntu/endtoend_venv/lib/python3.12/site-packages/airflow/models/taskinstance.py", line 465, in _execute_task
    result = _execute_callable(context=context, **execute_callable_kwargs)
             ^^^^^^^^^^^^^^^^^^^^^^^^^^^^^^^^^^^^^^^^^^^^^^^^^^^^^^^^^^^^^
  File "/home/ubuntu/endtoend_venv/lib/python3.12/site-packages/airflow/models/taskinstance.py", line 432, in _execute_callable
    return execute_callable(context=context, **execute_callable_kwargs)
           ^^^^^^^^^^^^^^^^^^^^^^^^^^^^^^^^^^^^^^^^^^^^^^^^^^^^^^^^^^^^
  File "/home/ubuntu/endtoend_venv/lib/python3.12/site-packages/airflow/models/baseoperator.py", line 400, in wrapper
    return func(self, *args, **kwargs)
           ^^^^^^^^^^^^^^^^^^^^^^^^^^^
  File "/home/ubuntu/endtoend_venv/lib/python3.12/site-packages/airflow/providers/amazon/aws/sensors/s3.py", line 183, in execute
    super().execute(context)
  File "/home/ubuntu/endtoend_venv/lib/python3.12/site-packages/airflow/models/baseoperator.py", line 400, in wrapper
    return func(self, *args, **kwargs)
           ^^^^^^^^^^^^^^^^^^^^^^^^^^^
  File "/home/ubuntu/endtoend_venv/lib/python3.12/site-packages/airflow/sensors/base.py", line 281, in execute
    raise AirflowSensorTimeout(message)
airflow.exceptions.AirflowSensorTimeout: Sensor has timed out; run duration of 20.440614511957392 seconds exceeds the specified timeout of 20.0.
[2024-06-14T02:20:14.162+0000] {taskinstance.py:1206} INFO - Immediate failure requested. Marking task as FAILED. dag_id=zillow_analytics_dag, task_id=tsk_is_file_in_s3_available, run_id=manual__2024-06-14T02:19:44.203462+00:00, execution_date=20240614T021944, start_date=20240614T021953, end_date=20240614T022014
[2024-06-14T02:20:14.174+0000] {standard_task_runner.py:110} ERROR - Failed to execute job 137 for task tsk_is_file_in_s3_available (Sensor has timed out; run duration of 20.440614511957392 seconds exceeds the specified timeout of 20.0.; 155179)
[2024-06-14T02:20:14.197+0000] {local_task_job_runner.py:240} INFO - Task exited with return code 1
[2024-06-14T02:20:14.206+0000] {taskinstance.py:3498} INFO - 0 downstream tasks scheduled from follow-on schedule check
[2024-06-14T02:20:14.207+0000] {local_task_job_runner.py:222} INFO - ::endgroup::
