[2024-06-08T05:12:38.549+0000] {local_task_job_runner.py:120} INFO - ::group::Pre task execution logs
[2024-06-08T05:12:38.566+0000] {taskinstance.py:2076} INFO - Dependencies all met for dep_context=non-requeueable deps ti=<TaskInstance: zillow_analytics_dag.tsk_load_to_s3 manual__2024-06-08T05:11:58.075314+00:00 [queued]>
[2024-06-08T05:12:38.573+0000] {taskinstance.py:2076} INFO - Dependencies all met for dep_context=requeueable deps ti=<TaskInstance: zillow_analytics_dag.tsk_load_to_s3 manual__2024-06-08T05:11:58.075314+00:00 [queued]>
[2024-06-08T05:12:38.573+0000] {taskinstance.py:2306} INFO - Starting attempt 3 of 3
[2024-06-08T05:12:38.587+0000] {taskinstance.py:2330} INFO - Executing <Task(BashOperator): tsk_load_to_s3> on 2024-06-08 05:11:58.075314+00:00
[2024-06-08T05:12:38.592+0000] {standard_task_runner.py:63} INFO - Started process 61056 to run task
[2024-06-08T05:12:38.595+0000] {standard_task_runner.py:90} INFO - Running: ['airflow', 'tasks', 'run', 'zillow_analytics_dag', 'tsk_load_to_s3', 'manual__2024-06-08T05:11:58.075314+00:00', '--job-id', '39', '--raw', '--subdir', 'DAGS_FOLDER/zillowanalytics.py', '--cfg-path', '/tmp/tmp02mczqnr']
[2024-06-08T05:12:38.596+0000] {standard_task_runner.py:91} INFO - Job 39: Subtask tsk_load_to_s3
[2024-06-08T05:12:38.633+0000] {task_command.py:426} INFO - Running <TaskInstance: zillow_analytics_dag.tsk_load_to_s3 manual__2024-06-08T05:11:58.075314+00:00 [running]> on host ip-172-31-25-20.us-east-2.compute.internal
[2024-06-08T05:12:38.698+0000] {taskinstance.py:2648} INFO - Exporting env vars: AIRFLOW_CTX_DAG_EMAIL='myemail@domain.com' AIRFLOW_CTX_DAG_OWNER='airflow' AIRFLOW_CTX_DAG_ID='zillow_analytics_dag' AIRFLOW_CTX_TASK_ID='tsk_load_to_s3' AIRFLOW_CTX_EXECUTION_DATE='2024-06-08T05:11:58.075314+00:00' AIRFLOW_CTX_TRY_NUMBER='3' AIRFLOW_CTX_DAG_RUN_ID='manual__2024-06-08T05:11:58.075314+00:00'
[2024-06-08T05:12:38.699+0000] {taskinstance.py:430} INFO - ::endgroup::
[2024-06-08T05:12:38.711+0000] {subprocess.py:63} INFO - Tmp dir root location: /tmp
[2024-06-08T05:12:38.712+0000] {subprocess.py:75} INFO - Running command: ['/usr/bin/bash', '-c', 'aws s3 mv /home/ubuntu/response_data_(dt_string).json s3://endtoend-zillow/']
[2024-06-08T05:12:38.720+0000] {subprocess.py:86} INFO - Output:
[2024-06-08T05:12:38.721+0000] {subprocess.py:93} INFO - /usr/bin/bash: -c: line 1: syntax error near unexpected token `('
[2024-06-08T05:12:38.721+0000] {subprocess.py:93} INFO - /usr/bin/bash: -c: line 1: `aws s3 mv /home/ubuntu/response_data_(dt_string).json s3://endtoend-zillow/'
[2024-06-08T05:12:38.722+0000] {subprocess.py:97} INFO - Command exited with return code 2
[2024-06-08T05:12:38.722+0000] {taskinstance.py:441} INFO - ::group::Post task execution logs
[2024-06-08T05:12:38.731+0000] {taskinstance.py:2905} ERROR - Task failed with exception
Traceback (most recent call last):
  File "/home/ubuntu/endtoend_venv/lib/python3.12/site-packages/airflow/models/taskinstance.py", line 465, in _execute_task
    result = _execute_callable(context=context, **execute_callable_kwargs)
             ^^^^^^^^^^^^^^^^^^^^^^^^^^^^^^^^^^^^^^^^^^^^^^^^^^^^^^^^^^^^^
  File "/home/ubuntu/endtoend_venv/lib/python3.12/site-packages/airflow/models/taskinstance.py", line 432, in _execute_callable
    return execute_callable(context=context, **execute_callable_kwargs)
           ^^^^^^^^^^^^^^^^^^^^^^^^^^^^^^^^^^^^^^^^^^^^^^^^^^^^^^^^^^^^
  File "/home/ubuntu/endtoend_venv/lib/python3.12/site-packages/airflow/models/baseoperator.py", line 400, in wrapper
    return func(self, *args, **kwargs)
           ^^^^^^^^^^^^^^^^^^^^^^^^^^^
  File "/home/ubuntu/endtoend_venv/lib/python3.12/site-packages/airflow/operators/bash.py", line 243, in execute
    raise AirflowException(
airflow.exceptions.AirflowException: Bash command failed. The command returned a non-zero exit code 2.
[2024-06-08T05:12:38.735+0000] {taskinstance.py:1206} INFO - Marking task as FAILED. dag_id=zillow_analytics_dag, task_id=tsk_load_to_s3, run_id=manual__2024-06-08T05:11:58.075314+00:00, execution_date=20240608T051158, start_date=20240608T051238, end_date=20240608T051238
[2024-06-08T05:12:38.747+0000] {standard_task_runner.py:110} ERROR - Failed to execute job 39 for task tsk_load_to_s3 (Bash command failed. The command returned a non-zero exit code 2.; 61056)
[2024-06-08T05:12:38.767+0000] {local_task_job_runner.py:240} INFO - Task exited with return code 1
[2024-06-08T05:12:38.778+0000] {taskinstance.py:3498} INFO - 0 downstream tasks scheduled from follow-on schedule check
[2024-06-08T05:12:38.779+0000] {local_task_job_runner.py:222} INFO - ::endgroup::
