[2024-06-15T02:36:35.917+0000] {local_task_job_runner.py:120} INFO - ::group::Pre task execution logs
[2024-06-15T02:36:35.930+0000] {taskinstance.py:2076} INFO - Dependencies all met for dep_context=non-requeueable deps ti=<TaskInstance: zillow_analytics_dag.tsk_transfer_s3_to_redshift manual__2024-06-15T02:30:18.500493+00:00 [queued]>
[2024-06-15T02:36:35.937+0000] {taskinstance.py:2076} INFO - Dependencies all met for dep_context=requeueable deps ti=<TaskInstance: zillow_analytics_dag.tsk_transfer_s3_to_redshift manual__2024-06-15T02:30:18.500493+00:00 [queued]>
[2024-06-15T02:36:35.938+0000] {taskinstance.py:2306} INFO - Starting attempt 3 of 3
[2024-06-15T02:36:35.953+0000] {taskinstance.py:2330} INFO - Executing <Task(S3ToRedshiftOperator): tsk_transfer_s3_to_redshift> on 2024-06-15 02:30:18.500493+00:00
[2024-06-15T02:36:35.959+0000] {standard_task_runner.py:63} INFO - Started process 185505 to run task
[2024-06-15T02:36:35.962+0000] {standard_task_runner.py:90} INFO - Running: ['airflow', 'tasks', 'run', 'zillow_analytics_dag', 'tsk_transfer_s3_to_redshift', 'manual__2024-06-15T02:30:18.500493+00:00', '--job-id', '209', '--raw', '--subdir', 'DAGS_FOLDER/zillowanalytics.py', '--cfg-path', '/tmp/tmpk9kojaul']
[2024-06-15T02:36:35.963+0000] {standard_task_runner.py:91} INFO - Job 209: Subtask tsk_transfer_s3_to_redshift
[2024-06-15T02:36:36.001+0000] {task_command.py:426} INFO - Running <TaskInstance: zillow_analytics_dag.tsk_transfer_s3_to_redshift manual__2024-06-15T02:30:18.500493+00:00 [running]> on host ip-172-31-25-20.us-east-2.compute.internal
[2024-06-15T02:36:36.071+0000] {taskinstance.py:2648} INFO - Exporting env vars: AIRFLOW_CTX_DAG_EMAIL='myemail@domain.com' AIRFLOW_CTX_DAG_OWNER='airflow' AIRFLOW_CTX_DAG_ID='zillow_analytics_dag' AIRFLOW_CTX_TASK_ID='tsk_transfer_s3_to_redshift' AIRFLOW_CTX_EXECUTION_DATE='2024-06-15T02:30:18.500493+00:00' AIRFLOW_CTX_TRY_NUMBER='3' AIRFLOW_CTX_DAG_RUN_ID='manual__2024-06-15T02:30:18.500493+00:00'
[2024-06-15T02:36:36.071+0000] {taskinstance.py:430} INFO - ::endgroup::
[2024-06-15T02:36:36.089+0000] {base.py:84} INFO - Using connection ID 'aws_s3_conn' for task execution.
[2024-06-15T02:36:36.091+0000] {base.py:84} INFO - Using connection ID 'aws_s3_conn' for task execution.
[2024-06-15T02:36:36.091+0000] {connection_wrapper.py:384} INFO - AWS Connection (conn_id='aws_s3_conn', conn_type='aws') credentials retrieved from login and password.
[2024-06-15T02:36:36.104+0000] {s3_to_redshift.py:193} INFO - Executing COPY command...
[2024-06-15T02:36:36.107+0000] {base.py:84} INFO - Using connection ID 'conn_id_redshift' for task execution.
[2024-06-15T02:38:49.907+0000] {taskinstance.py:441} INFO - ::group::Post task execution logs
[2024-06-15T02:38:49.908+0000] {taskinstance.py:2905} ERROR - Task failed with exception
Traceback (most recent call last):
  File "/home/ubuntu/endtoend_venv/lib/python3.12/site-packages/redshift_connector/core.py", line 626, in __init__
    self._usock.connect(hostport)
TimeoutError: [Errno 110] Connection timed out

During handling of the above exception, another exception occurred:

Traceback (most recent call last):
  File "/home/ubuntu/endtoend_venv/lib/python3.12/site-packages/airflow/models/taskinstance.py", line 465, in _execute_task
    result = _execute_callable(context=context, **execute_callable_kwargs)
             ^^^^^^^^^^^^^^^^^^^^^^^^^^^^^^^^^^^^^^^^^^^^^^^^^^^^^^^^^^^^^
  File "/home/ubuntu/endtoend_venv/lib/python3.12/site-packages/airflow/models/taskinstance.py", line 432, in _execute_callable
    return execute_callable(context=context, **execute_callable_kwargs)
           ^^^^^^^^^^^^^^^^^^^^^^^^^^^^^^^^^^^^^^^^^^^^^^^^^^^^^^^^^^^^
  File "/home/ubuntu/endtoend_venv/lib/python3.12/site-packages/airflow/models/baseoperator.py", line 400, in wrapper
    return func(self, *args, **kwargs)
           ^^^^^^^^^^^^^^^^^^^^^^^^^^^
  File "/home/ubuntu/endtoend_venv/lib/python3.12/site-packages/airflow/providers/amazon/aws/transfers/s3_to_redshift.py", line 197, in execute
    redshift_hook.run(sql, autocommit=self.autocommit)
  File "/home/ubuntu/endtoend_venv/lib/python3.12/site-packages/airflow/providers/common/sql/hooks/sql.py", line 431, in run
    with self._create_autocommit_connection(autocommit) as conn:
  File "/usr/lib/python3.12/contextlib.py", line 137, in __enter__
    return next(self.gen)
           ^^^^^^^^^^^^^^
  File "/home/ubuntu/endtoend_venv/lib/python3.12/site-packages/airflow/providers/common/sql/hooks/sql.py", line 551, in _create_autocommit_connection
    with closing(self.get_conn()) as conn:
                 ^^^^^^^^^^^^^^^
  File "/home/ubuntu/endtoend_venv/lib/python3.12/site-packages/airflow/providers/amazon/aws/hooks/redshift_sql.py", line 200, in get_conn
    return redshift_connector.connect(**conn_kwargs)
           ^^^^^^^^^^^^^^^^^^^^^^^^^^^^^^^^^^^^^^^^^
  File "/home/ubuntu/endtoend_venv/lib/python3.12/site-packages/redshift_connector/__init__.py", line 378, in connect
    return Connection(
           ^^^^^^^^^^^
  File "/home/ubuntu/endtoend_venv/lib/python3.12/site-packages/redshift_connector/core.py", line 681, in __init__
    raise OperationalError("connection time out", timeout_error)
redshift_connector.error.OperationalError: ('connection time out', TimeoutError(110, 'Connection timed out'))
[2024-06-15T02:38:49.913+0000] {taskinstance.py:1206} INFO - Marking task as FAILED. dag_id=zillow_analytics_dag, task_id=tsk_transfer_s3_to_redshift, run_id=manual__2024-06-15T02:30:18.500493+00:00, execution_date=20240615T023018, start_date=20240615T023635, end_date=20240615T023849
[2024-06-15T02:38:49.926+0000] {standard_task_runner.py:110} ERROR - Failed to execute job 209 for task tsk_transfer_s3_to_redshift (('connection time out', TimeoutError(110, 'Connection timed out')); 185505)
[2024-06-15T02:38:49.953+0000] {local_task_job_runner.py:240} INFO - Task exited with return code 1
[2024-06-15T02:38:49.961+0000] {taskinstance.py:3498} INFO - 0 downstream tasks scheduled from follow-on schedule check
[2024-06-15T02:38:49.962+0000] {local_task_job_runner.py:222} INFO - ::endgroup::
