[2024-06-15T00:00:09.414+0000] {local_task_job_runner.py:120} INFO - ::group::Pre task execution logs
[2024-06-15T00:00:09.425+0000] {taskinstance.py:2076} INFO - Dependencies all met for dep_context=non-requeueable deps ti=<TaskInstance: zillow_analytics_dag.tsk_is_file_in_s3_available scheduled__2024-06-14T00:00:00+00:00 [queued]>
[2024-06-15T00:00:09.431+0000] {taskinstance.py:2076} INFO - Dependencies all met for dep_context=requeueable deps ti=<TaskInstance: zillow_analytics_dag.tsk_is_file_in_s3_available scheduled__2024-06-14T00:00:00+00:00 [queued]>
[2024-06-15T00:00:09.431+0000] {taskinstance.py:2306} INFO - Starting attempt 1 of 3
[2024-06-15T00:00:09.446+0000] {taskinstance.py:2330} INFO - Executing <Task(S3KeySensor): tsk_is_file_in_s3_available> on 2024-06-14 00:00:00+00:00
[2024-06-15T00:00:09.451+0000] {standard_task_runner.py:63} INFO - Started process 181350 to run task
[2024-06-15T00:00:09.454+0000] {standard_task_runner.py:90} INFO - Running: ['airflow', 'tasks', 'run', 'zillow_analytics_dag', 'tsk_is_file_in_s3_available', 'scheduled__2024-06-14T00:00:00+00:00', '--job-id', '201', '--raw', '--subdir', 'DAGS_FOLDER/zillowanalytics.py', '--cfg-path', '/tmp/tmp6584t_wt']
[2024-06-15T00:00:09.455+0000] {standard_task_runner.py:91} INFO - Job 201: Subtask tsk_is_file_in_s3_available
[2024-06-15T00:00:09.493+0000] {task_command.py:426} INFO - Running <TaskInstance: zillow_analytics_dag.tsk_is_file_in_s3_available scheduled__2024-06-14T00:00:00+00:00 [running]> on host ip-172-31-25-20.us-east-2.compute.internal
[2024-06-15T00:00:09.573+0000] {taskinstance.py:2648} INFO - Exporting env vars: AIRFLOW_CTX_DAG_EMAIL='myemail@domain.com' AIRFLOW_CTX_DAG_OWNER='airflow' AIRFLOW_CTX_DAG_ID='zillow_analytics_dag' AIRFLOW_CTX_TASK_ID='tsk_is_file_in_s3_available' AIRFLOW_CTX_EXECUTION_DATE='2024-06-14T00:00:00+00:00' AIRFLOW_CTX_TRY_NUMBER='1' AIRFLOW_CTX_DAG_RUN_ID='scheduled__2024-06-14T00:00:00+00:00'
[2024-06-15T00:00:09.573+0000] {taskinstance.py:430} INFO - ::endgroup::
[2024-06-15T00:00:09.586+0000] {baseoperator.py:399} WARNING - S3KeySensor.execute cannot be called outside TaskInstance!
[2024-06-15T00:00:09.586+0000] {s3.py:117} INFO - Poking for key : s3://cleaned-data-zone-csv-bucket-ng/response_data_15062024000002.csv
[2024-06-15T00:00:09.591+0000] {base.py:84} INFO - Using connection ID 'aws_s3_conn' for task execution.
[2024-06-15T00:00:09.592+0000] {connection_wrapper.py:384} INFO - AWS Connection (conn_id='aws_s3_conn', conn_type='aws') credentials retrieved from login and password.
[2024-06-15T00:00:15.009+0000] {s3.py:117} INFO - Poking for key : s3://cleaned-data-zone-csv-bucket-ng/response_data_15062024000002.csv
[2024-06-15T00:00:20.033+0000] {s3.py:117} INFO - Poking for key : s3://cleaned-data-zone-csv-bucket-ng/response_data_15062024000002.csv
[2024-06-15T00:00:25.044+0000] {s3.py:117} INFO - Poking for key : s3://cleaned-data-zone-csv-bucket-ng/response_data_15062024000002.csv
[2024-06-15T00:00:30.054+0000] {s3.py:117} INFO - Poking for key : s3://cleaned-data-zone-csv-bucket-ng/response_data_15062024000002.csv
[2024-06-15T00:00:35.063+0000] {s3.py:117} INFO - Poking for key : s3://cleaned-data-zone-csv-bucket-ng/response_data_15062024000002.csv
[2024-06-15T00:00:40.073+0000] {s3.py:117} INFO - Poking for key : s3://cleaned-data-zone-csv-bucket-ng/response_data_15062024000002.csv
[2024-06-15T00:00:45.081+0000] {s3.py:117} INFO - Poking for key : s3://cleaned-data-zone-csv-bucket-ng/response_data_15062024000002.csv
[2024-06-15T00:00:50.092+0000] {s3.py:117} INFO - Poking for key : s3://cleaned-data-zone-csv-bucket-ng/response_data_15062024000002.csv
[2024-06-15T00:00:55.100+0000] {s3.py:117} INFO - Poking for key : s3://cleaned-data-zone-csv-bucket-ng/response_data_15062024000002.csv
[2024-06-15T00:01:00.108+0000] {s3.py:117} INFO - Poking for key : s3://cleaned-data-zone-csv-bucket-ng/response_data_15062024000002.csv
[2024-06-15T00:01:05.115+0000] {s3.py:117} INFO - Poking for key : s3://cleaned-data-zone-csv-bucket-ng/response_data_15062024000002.csv
[2024-06-15T00:01:10.123+0000] {s3.py:117} INFO - Poking for key : s3://cleaned-data-zone-csv-bucket-ng/response_data_15062024000002.csv
[2024-06-15T00:01:10.132+0000] {taskinstance.py:441} INFO - ::group::Post task execution logs
[2024-06-15T00:01:10.132+0000] {taskinstance.py:2905} ERROR - Task failed with exception
Traceback (most recent call last):
  File "/home/ubuntu/endtoend_venv/lib/python3.12/site-packages/airflow/models/taskinstance.py", line 465, in _execute_task
    result = _execute_callable(context=context, **execute_callable_kwargs)
             ^^^^^^^^^^^^^^^^^^^^^^^^^^^^^^^^^^^^^^^^^^^^^^^^^^^^^^^^^^^^^
  File "/home/ubuntu/endtoend_venv/lib/python3.12/site-packages/airflow/models/taskinstance.py", line 432, in _execute_callable
    return execute_callable(context=context, **execute_callable_kwargs)
           ^^^^^^^^^^^^^^^^^^^^^^^^^^^^^^^^^^^^^^^^^^^^^^^^^^^^^^^^^^^^
  File "/home/ubuntu/endtoend_venv/lib/python3.12/site-packages/airflow/models/baseoperator.py", line 400, in wrapper
    return func(self, *args, **kwargs)
           ^^^^^^^^^^^^^^^^^^^^^^^^^^^
  File "/home/ubuntu/endtoend_venv/lib/python3.12/site-packages/airflow/providers/amazon/aws/sensors/s3.py", line 183, in execute
    super().execute(context)
  File "/home/ubuntu/endtoend_venv/lib/python3.12/site-packages/airflow/models/baseoperator.py", line 400, in wrapper
    return func(self, *args, **kwargs)
           ^^^^^^^^^^^^^^^^^^^^^^^^^^^
  File "/home/ubuntu/endtoend_venv/lib/python3.12/site-packages/airflow/sensors/base.py", line 281, in execute
    raise AirflowSensorTimeout(message)
airflow.exceptions.AirflowSensorTimeout: Sensor has timed out; run duration of 60.545834525022656 seconds exceeds the specified timeout of 60.0.
[2024-06-15T00:01:10.137+0000] {taskinstance.py:1206} INFO - Immediate failure requested. Marking task as FAILED. dag_id=zillow_analytics_dag, task_id=tsk_is_file_in_s3_available, run_id=scheduled__2024-06-14T00:00:00+00:00, execution_date=20240614T000000, start_date=20240615T000009, end_date=20240615T000110
[2024-06-15T00:01:10.149+0000] {standard_task_runner.py:110} ERROR - Failed to execute job 201 for task tsk_is_file_in_s3_available (Sensor has timed out; run duration of 60.545834525022656 seconds exceeds the specified timeout of 60.0.; 181350)
[2024-06-15T00:01:10.160+0000] {local_task_job_runner.py:240} INFO - Task exited with return code 1
[2024-06-15T00:01:10.179+0000] {taskinstance.py:3498} INFO - 0 downstream tasks scheduled from follow-on schedule check
[2024-06-15T00:01:10.185+0000] {local_task_job_runner.py:222} INFO - ::endgroup::
