[2024-06-14T02:56:51.436+0000] {local_task_job_runner.py:120} INFO - ::group::Pre task execution logs
[2024-06-14T02:56:51.445+0000] {taskinstance.py:2076} INFO - Dependencies all met for dep_context=non-requeueable deps ti=<TaskInstance: zillow_analytics_dag.tsk_is_file_in_s3_available manual__2024-06-14T02:56:42.736318+00:00 [queued]>
[2024-06-14T02:56:51.452+0000] {taskinstance.py:2076} INFO - Dependencies all met for dep_context=requeueable deps ti=<TaskInstance: zillow_analytics_dag.tsk_is_file_in_s3_available manual__2024-06-14T02:56:42.736318+00:00 [queued]>
[2024-06-14T02:56:51.452+0000] {taskinstance.py:2306} INFO - Starting attempt 1 of 3
[2024-06-14T02:56:51.467+0000] {taskinstance.py:2330} INFO - Executing <Task(S3KeySensor): tsk_is_file_in_s3_available> on 2024-06-14 02:56:42.736318+00:00
[2024-06-14T02:56:51.471+0000] {standard_task_runner.py:63} INFO - Started process 158710 to run task
[2024-06-14T02:56:51.475+0000] {standard_task_runner.py:90} INFO - Running: ['airflow', 'tasks', 'run', 'zillow_analytics_dag', 'tsk_is_file_in_s3_available', 'manual__2024-06-14T02:56:42.736318+00:00', '--job-id', '172', '--raw', '--subdir', 'DAGS_FOLDER/zillowanalytics.py', '--cfg-path', '/tmp/tmp5zr2g9vw']
[2024-06-14T02:56:51.477+0000] {standard_task_runner.py:91} INFO - Job 172: Subtask tsk_is_file_in_s3_available
[2024-06-14T02:56:51.511+0000] {task_command.py:426} INFO - Running <TaskInstance: zillow_analytics_dag.tsk_is_file_in_s3_available manual__2024-06-14T02:56:42.736318+00:00 [running]> on host ip-172-31-25-20.us-east-2.compute.internal
[2024-06-14T02:56:51.586+0000] {taskinstance.py:2648} INFO - Exporting env vars: AIRFLOW_CTX_DAG_EMAIL='myemail@domain.com' AIRFLOW_CTX_DAG_OWNER='airflow' AIRFLOW_CTX_DAG_ID='zillow_analytics_dag' AIRFLOW_CTX_TASK_ID='tsk_is_file_in_s3_available' AIRFLOW_CTX_EXECUTION_DATE='2024-06-14T02:56:42.736318+00:00' AIRFLOW_CTX_TRY_NUMBER='1' AIRFLOW_CTX_DAG_RUN_ID='manual__2024-06-14T02:56:42.736318+00:00'
[2024-06-14T02:56:51.587+0000] {taskinstance.py:430} INFO - ::endgroup::
[2024-06-14T02:56:51.599+0000] {baseoperator.py:399} WARNING - S3KeySensor.execute cannot be called outside TaskInstance!
[2024-06-14T02:56:51.599+0000] {s3.py:117} INFO - Poking for key : s3://cleaned-data-zone-csv-bucket-ng/response_data_14062024025644.json
[2024-06-14T02:56:51.604+0000] {base.py:84} INFO - Using connection ID 'aws_s3_conn' for task execution.
[2024-06-14T02:56:51.605+0000] {connection_wrapper.py:384} INFO - AWS Connection (conn_id='aws_s3_conn', conn_type='aws') credentials retrieved from login and password.
[2024-06-14T02:56:57.007+0000] {s3.py:117} INFO - Poking for key : s3://cleaned-data-zone-csv-bucket-ng/response_data_14062024025644.json
[2024-06-14T02:57:02.017+0000] {s3.py:117} INFO - Poking for key : s3://cleaned-data-zone-csv-bucket-ng/response_data_14062024025644.json
[2024-06-14T02:57:07.026+0000] {s3.py:117} INFO - Poking for key : s3://cleaned-data-zone-csv-bucket-ng/response_data_14062024025644.json
[2024-06-14T02:57:12.035+0000] {s3.py:117} INFO - Poking for key : s3://cleaned-data-zone-csv-bucket-ng/response_data_14062024025644.json
[2024-06-14T02:57:17.046+0000] {s3.py:117} INFO - Poking for key : s3://cleaned-data-zone-csv-bucket-ng/response_data_14062024025644.json
[2024-06-14T02:57:22.055+0000] {s3.py:117} INFO - Poking for key : s3://cleaned-data-zone-csv-bucket-ng/response_data_14062024025644.json
[2024-06-14T02:57:27.067+0000] {s3.py:117} INFO - Poking for key : s3://cleaned-data-zone-csv-bucket-ng/response_data_14062024025644.json
[2024-06-14T02:57:32.078+0000] {s3.py:117} INFO - Poking for key : s3://cleaned-data-zone-csv-bucket-ng/response_data_14062024025644.json
[2024-06-14T02:57:37.087+0000] {s3.py:117} INFO - Poking for key : s3://cleaned-data-zone-csv-bucket-ng/response_data_14062024025644.json
[2024-06-14T02:57:42.099+0000] {s3.py:117} INFO - Poking for key : s3://cleaned-data-zone-csv-bucket-ng/response_data_14062024025644.json
[2024-06-14T02:57:47.108+0000] {s3.py:117} INFO - Poking for key : s3://cleaned-data-zone-csv-bucket-ng/response_data_14062024025644.json
[2024-06-14T02:57:52.117+0000] {s3.py:117} INFO - Poking for key : s3://cleaned-data-zone-csv-bucket-ng/response_data_14062024025644.json
[2024-06-14T02:57:57.130+0000] {s3.py:117} INFO - Poking for key : s3://cleaned-data-zone-csv-bucket-ng/response_data_14062024025644.json
[2024-06-14T02:58:02.140+0000] {s3.py:117} INFO - Poking for key : s3://cleaned-data-zone-csv-bucket-ng/response_data_14062024025644.json
[2024-06-14T02:58:07.152+0000] {s3.py:117} INFO - Poking for key : s3://cleaned-data-zone-csv-bucket-ng/response_data_14062024025644.json
[2024-06-14T02:58:12.163+0000] {s3.py:117} INFO - Poking for key : s3://cleaned-data-zone-csv-bucket-ng/response_data_14062024025644.json
[2024-06-14T02:58:17.171+0000] {s3.py:117} INFO - Poking for key : s3://cleaned-data-zone-csv-bucket-ng/response_data_14062024025644.json
[2024-06-14T02:58:22.182+0000] {s3.py:117} INFO - Poking for key : s3://cleaned-data-zone-csv-bucket-ng/response_data_14062024025644.json
[2024-06-14T02:58:27.193+0000] {s3.py:117} INFO - Poking for key : s3://cleaned-data-zone-csv-bucket-ng/response_data_14062024025644.json
[2024-06-14T02:58:32.201+0000] {s3.py:117} INFO - Poking for key : s3://cleaned-data-zone-csv-bucket-ng/response_data_14062024025644.json
[2024-06-14T02:58:37.211+0000] {s3.py:117} INFO - Poking for key : s3://cleaned-data-zone-csv-bucket-ng/response_data_14062024025644.json
[2024-06-14T02:58:42.224+0000] {s3.py:117} INFO - Poking for key : s3://cleaned-data-zone-csv-bucket-ng/response_data_14062024025644.json
[2024-06-14T02:58:47.232+0000] {s3.py:117} INFO - Poking for key : s3://cleaned-data-zone-csv-bucket-ng/response_data_14062024025644.json
[2024-06-14T02:58:52.242+0000] {s3.py:117} INFO - Poking for key : s3://cleaned-data-zone-csv-bucket-ng/response_data_14062024025644.json
[2024-06-14T02:58:52.255+0000] {taskinstance.py:441} INFO - ::group::Post task execution logs
[2024-06-14T02:58:52.255+0000] {taskinstance.py:2905} ERROR - Task failed with exception
Traceback (most recent call last):
  File "/home/ubuntu/endtoend_venv/lib/python3.12/site-packages/airflow/models/taskinstance.py", line 465, in _execute_task
    result = _execute_callable(context=context, **execute_callable_kwargs)
             ^^^^^^^^^^^^^^^^^^^^^^^^^^^^^^^^^^^^^^^^^^^^^^^^^^^^^^^^^^^^^
  File "/home/ubuntu/endtoend_venv/lib/python3.12/site-packages/airflow/models/taskinstance.py", line 432, in _execute_callable
    return execute_callable(context=context, **execute_callable_kwargs)
           ^^^^^^^^^^^^^^^^^^^^^^^^^^^^^^^^^^^^^^^^^^^^^^^^^^^^^^^^^^^^
  File "/home/ubuntu/endtoend_venv/lib/python3.12/site-packages/airflow/models/baseoperator.py", line 400, in wrapper
    return func(self, *args, **kwargs)
           ^^^^^^^^^^^^^^^^^^^^^^^^^^^
  File "/home/ubuntu/endtoend_venv/lib/python3.12/site-packages/airflow/providers/amazon/aws/sensors/s3.py", line 183, in execute
    super().execute(context)
  File "/home/ubuntu/endtoend_venv/lib/python3.12/site-packages/airflow/models/baseoperator.py", line 400, in wrapper
    return func(self, *args, **kwargs)
           ^^^^^^^^^^^^^^^^^^^^^^^^^^^
  File "/home/ubuntu/endtoend_venv/lib/python3.12/site-packages/airflow/sensors/base.py", line 281, in execute
    raise AirflowSensorTimeout(message)
airflow.exceptions.AirflowSensorTimeout: Sensor has timed out; run duration of 120.6557503080694 seconds exceeds the specified timeout of 120.0.
[2024-06-14T02:58:52.260+0000] {taskinstance.py:1206} INFO - Immediate failure requested. Marking task as FAILED. dag_id=zillow_analytics_dag, task_id=tsk_is_file_in_s3_available, run_id=manual__2024-06-14T02:56:42.736318+00:00, execution_date=20240614T025642, start_date=20240614T025651, end_date=20240614T025852
[2024-06-14T02:58:52.271+0000] {standard_task_runner.py:110} ERROR - Failed to execute job 172 for task tsk_is_file_in_s3_available (Sensor has timed out; run duration of 120.6557503080694 seconds exceeds the specified timeout of 120.0.; 158710)
[2024-06-14T02:58:52.288+0000] {local_task_job_runner.py:240} INFO - Task exited with return code 1
[2024-06-14T02:58:52.297+0000] {taskinstance.py:3498} INFO - 0 downstream tasks scheduled from follow-on schedule check
[2024-06-14T02:58:52.297+0000] {local_task_job_runner.py:222} INFO - ::endgroup::
